<?xml version="1.0" encoding="UTF-8"?>
<testng-results ignored="0" total="5" passed="2" failed="3" skipped="0">
  <reporter-output>
  </reporter-output>
  <suite started-at="2023-10-30T00:38:25 IST" name="Suite" finished-at="2023-10-30T00:38:35 IST" duration-ms="9888">
    <groups>
    </groups>
    <test started-at="2023-10-30T00:38:25 IST" name="Test" finished-at="2023-10-30T00:38:35 IST" duration-ms="9888">
      <class name="TestClassPackage.Delete_TC1">
        <test-method signature="Executer()[pri:0, instance:TestClassPackage.Delete_TC1@5ddcc487]" started-at="2023-10-30T00:38:32 IST" name="Executer" finished-at="2023-10-30T00:38:32 IST" duration-ms="453" status="PASS">
          <reporter-output>
          </reporter-output>
        </test-method> <!-- Executer -->
      </class> <!-- TestClassPackage.Delete_TC1 -->
      <class name="TestClassPackage.Put_TC1">
        <test-method signature="Executer()[pri:0, instance:TestClassPackage.Put_TC1@17d88132]" started-at="2023-10-30T00:38:31 IST" name="Executer" finished-at="2023-10-30T00:38:32 IST" duration-ms="1066" status="FAIL">
          <exception class="java.lang.AssertionError">
            <message>
              <![CDATA[expected [2023-10-30T] but found [2023-10-29T]]]>
            </message>
            <full-stacktrace>
              <![CDATA[java.lang.AssertionError: expected [2023-10-30T] but found [2023-10-29T]
at org.testng.Assert.fail(Assert.java:110)
at org.testng.Assert.failNotEquals(Assert.java:1577)
at org.testng.Assert.assertEqualsImpl(Assert.java:149)
at org.testng.Assert.assertEquals(Assert.java:131)
at org.testng.Assert.assertEquals(Assert.java:655)
at org.testng.Assert.assertEquals(Assert.java:665)
at TestClassPackage.Put_TC1.Validator(Put_TC1.java:66)
at TestClassPackage.Put_TC1.Executer(Put_TC1.java:35)
at java.base/jdk.internal.reflect.NativeMethodAccessorImpl.invoke0(Native Method)
at java.base/jdk.internal.reflect.NativeMethodAccessorImpl.invoke(NativeMethodAccessorImpl.java:77)
at java.base/jdk.internal.reflect.DelegatingMethodAccessorImpl.invoke(DelegatingMethodAccessorImpl.java:43)
at java.base/java.lang.reflect.Method.invoke(Method.java:568)
at org.testng.internal.invokers.MethodInvocationHelper.invokeMethod(MethodInvocationHelper.java:139)
at org.testng.internal.invokers.TestInvoker.invokeMethod(TestInvoker.java:677)
at org.testng.internal.invokers.TestInvoker.invokeTestMethod(TestInvoker.java:221)
at org.testng.internal.invokers.MethodRunner.runInSequence(MethodRunner.java:50)
at org.testng.internal.invokers.TestInvoker$MethodInvocationAgent.invoke(TestInvoker.java:969)
at org.testng.internal.invokers.TestInvoker.invokeTestMethods(TestInvoker.java:194)
at org.testng.internal.invokers.TestMethodWorker.invokeTestMethods(TestMethodWorker.java:148)
at org.testng.internal.invokers.TestMethodWorker.run(TestMethodWorker.java:128)
at java.base/java.util.ArrayList.forEach(ArrayList.java:1511)
at org.testng.TestRunner.privateRun(TestRunner.java:829)
at org.testng.TestRunner.run(TestRunner.java:602)
at org.testng.SuiteRunner.runTest(SuiteRunner.java:437)
at org.testng.SuiteRunner.runSequentially(SuiteRunner.java:431)
at org.testng.SuiteRunner.privateRun(SuiteRunner.java:391)
at org.testng.SuiteRunner.run(SuiteRunner.java:330)
at org.testng.SuiteRunnerWorker.runSuite(SuiteRunnerWorker.java:52)
at org.testng.SuiteRunnerWorker.run(SuiteRunnerWorker.java:95)
at org.testng.TestNG.runSuitesSequentially(TestNG.java:1256)
at org.testng.TestNG.runSuitesLocally(TestNG.java:1176)
at org.testng.TestNG.runSuites(TestNG.java:1099)
at org.testng.TestNG.run(TestNG.java:1067)
at org.testng.remote.AbstractRemoteTestNG.run(AbstractRemoteTestNG.java:115)
at org.testng.remote.RemoteTestNG.initAndRun(RemoteTestNG.java:251)
at org.testng.remote.RemoteTestNG.main(RemoteTestNG.java:77)
]]>
            </full-stacktrace>
          </exception> <!-- java.lang.AssertionError -->
          <reporter-output>
          </reporter-output>
        </test-method> <!-- Executer -->
      </class> <!-- TestClassPackage.Put_TC1 -->
      <class name="TestClassPackage.Post_TC1">
        <test-method signature="Executer()[pri:0, instance:TestClassPackage.Post_TC1@31add175]" started-at="2023-10-30T00:38:25 IST" name="Executer" finished-at="2023-10-30T00:38:31 IST" duration-ms="6101" status="FAIL">
          <exception class="java.lang.AssertionError">
            <message>
              <![CDATA[expected [2023-10-29T] but found [2023-10-30T]]]>
            </message>
            <full-stacktrace>
              <![CDATA[java.lang.AssertionError: expected [2023-10-29T] but found [2023-10-30T]
at org.testng.Assert.fail(Assert.java:110)
at org.testng.Assert.failNotEquals(Assert.java:1577)
at org.testng.Assert.assertEqualsImpl(Assert.java:149)
at org.testng.Assert.assertEquals(Assert.java:131)
at org.testng.Assert.assertEquals(Assert.java:655)
at org.testng.Assert.assertEquals(Assert.java:665)
at TestClassPackage.Post_TC1.Validator(Post_TC1.java:72)
at TestClassPackage.Post_TC1.Executer(Post_TC1.java:39)
at java.base/jdk.internal.reflect.NativeMethodAccessorImpl.invoke0(Native Method)
at java.base/jdk.internal.reflect.NativeMethodAccessorImpl.invoke(NativeMethodAccessorImpl.java:77)
at java.base/jdk.internal.reflect.DelegatingMethodAccessorImpl.invoke(DelegatingMethodAccessorImpl.java:43)
at java.base/java.lang.reflect.Method.invoke(Method.java:568)
at org.testng.internal.invokers.MethodInvocationHelper.invokeMethod(MethodInvocationHelper.java:139)
at org.testng.internal.invokers.TestInvoker.invokeMethod(TestInvoker.java:677)
at org.testng.internal.invokers.TestInvoker.invokeTestMethod(TestInvoker.java:221)
at org.testng.internal.invokers.MethodRunner.runInSequence(MethodRunner.java:50)
at org.testng.internal.invokers.TestInvoker$MethodInvocationAgent.invoke(TestInvoker.java:969)
at org.testng.internal.invokers.TestInvoker.invokeTestMethods(TestInvoker.java:194)
at org.testng.internal.invokers.TestMethodWorker.invokeTestMethods(TestMethodWorker.java:148)
at org.testng.internal.invokers.TestMethodWorker.run(TestMethodWorker.java:128)
at java.base/java.util.ArrayList.forEach(ArrayList.java:1511)
at org.testng.TestRunner.privateRun(TestRunner.java:829)
at org.testng.TestRunner.run(TestRunner.java:602)
at org.testng.SuiteRunner.runTest(SuiteRunner.java:437)
at org.testng.SuiteRunner.runSequentially(SuiteRunner.java:431)
at org.testng.SuiteRunner.privateRun(SuiteRunner.java:391)
at org.testng.SuiteRunner.run(SuiteRunner.java:330)
at org.testng.SuiteRunnerWorker.runSuite(SuiteRunnerWorker.java:52)
at org.testng.SuiteRunnerWorker.run(SuiteRunnerWorker.java:95)
at org.testng.TestNG.runSuitesSequentially(TestNG.java:1256)
at org.testng.TestNG.runSuitesLocally(TestNG.java:1176)
at org.testng.TestNG.runSuites(TestNG.java:1099)
at org.testng.TestNG.run(TestNG.java:1067)
at org.testng.remote.AbstractRemoteTestNG.run(AbstractRemoteTestNG.java:115)
at org.testng.remote.RemoteTestNG.initAndRun(RemoteTestNG.java:251)
at org.testng.remote.RemoteTestNG.main(RemoteTestNG.java:77)
]]>
            </full-stacktrace>
          </exception> <!-- java.lang.AssertionError -->
          <reporter-output>
          </reporter-output>
        </test-method> <!-- Executer -->
      </class> <!-- TestClassPackage.Post_TC1 -->
      <class name="TestClassPackage.Get_TC1">
        <test-method signature="Executer()[pri:0, instance:TestClassPackage.Get_TC1@5ef5c734]" started-at="2023-10-30T00:38:33 IST" name="Executer" finished-at="2023-10-30T00:38:34 IST" duration-ms="1040" status="PASS">
          <reporter-output>
          </reporter-output>
        </test-method> <!-- Executer -->
      </class> <!-- TestClassPackage.Get_TC1 -->
      <class name="TestClassPackage.Patch_TC1">
        <test-method signature="Executer()[pri:0, instance:TestClassPackage.Patch_TC1@16eccb2e]" started-at="2023-10-30T00:38:32 IST" name="Executer" finished-at="2023-10-30T00:38:33 IST" duration-ms="971" status="FAIL">
          <exception class="java.lang.AssertionError">
            <message>
              <![CDATA[expected [2023-10-29T] but found [2023-10-30T]]]>
            </message>
            <full-stacktrace>
              <![CDATA[java.lang.AssertionError: expected [2023-10-29T] but found [2023-10-30T]
at org.testng.Assert.fail(Assert.java:110)
at org.testng.Assert.failNotEquals(Assert.java:1577)
at org.testng.Assert.assertEqualsImpl(Assert.java:149)
at org.testng.Assert.assertEquals(Assert.java:131)
at org.testng.Assert.assertEquals(Assert.java:655)
at org.testng.Assert.assertEquals(Assert.java:665)
at TestClassPackage.Patch_TC1.Validator(Patch_TC1.java:67)
at TestClassPackage.Patch_TC1.Executer(Patch_TC1.java:36)
at java.base/jdk.internal.reflect.NativeMethodAccessorImpl.invoke0(Native Method)
at java.base/jdk.internal.reflect.NativeMethodAccessorImpl.invoke(NativeMethodAccessorImpl.java:77)
at java.base/jdk.internal.reflect.DelegatingMethodAccessorImpl.invoke(DelegatingMethodAccessorImpl.java:43)
at java.base/java.lang.reflect.Method.invoke(Method.java:568)
at org.testng.internal.invokers.MethodInvocationHelper.invokeMethod(MethodInvocationHelper.java:139)
at org.testng.internal.invokers.TestInvoker.invokeMethod(TestInvoker.java:677)
at org.testng.internal.invokers.TestInvoker.invokeTestMethod(TestInvoker.java:221)
at org.testng.internal.invokers.MethodRunner.runInSequence(MethodRunner.java:50)
at org.testng.internal.invokers.TestInvoker$MethodInvocationAgent.invoke(TestInvoker.java:969)
at org.testng.internal.invokers.TestInvoker.invokeTestMethods(TestInvoker.java:194)
at org.testng.internal.invokers.TestMethodWorker.invokeTestMethods(TestMethodWorker.java:148)
at org.testng.internal.invokers.TestMethodWorker.run(TestMethodWorker.java:128)
at java.base/java.util.ArrayList.forEach(ArrayList.java:1511)
at org.testng.TestRunner.privateRun(TestRunner.java:829)
at org.testng.TestRunner.run(TestRunner.java:602)
at org.testng.SuiteRunner.runTest(SuiteRunner.java:437)
at org.testng.SuiteRunner.runSequentially(SuiteRunner.java:431)
at org.testng.SuiteRunner.privateRun(SuiteRunner.java:391)
at org.testng.SuiteRunner.run(SuiteRunner.java:330)
at org.testng.SuiteRunnerWorker.runSuite(SuiteRunnerWorker.java:52)
at org.testng.SuiteRunnerWorker.run(SuiteRunnerWorker.java:95)
at org.testng.TestNG.runSuitesSequentially(TestNG.java:1256)
at org.testng.TestNG.runSuitesLocally(TestNG.java:1176)
at org.testng.TestNG.runSuites(TestNG.java:1099)
at org.testng.TestNG.run(TestNG.java:1067)
at org.testng.remote.AbstractRemoteTestNG.run(AbstractRemoteTestNG.java:115)
at org.testng.remote.RemoteTestNG.initAndRun(RemoteTestNG.java:251)
at org.testng.remote.RemoteTestNG.main(RemoteTestNG.java:77)
]]>
            </full-stacktrace>
          </exception> <!-- java.lang.AssertionError -->
          <reporter-output>
          </reporter-output>
        </test-method> <!-- Executer -->
      </class> <!-- TestClassPackage.Patch_TC1 -->
    </test> <!-- Test -->
  </suite> <!-- Suite -->
</testng-results>
